Traceback (most recent call last):
  File "/Users/seanwalsh/Documents/GitHub-Mac-Desktop-New/philcompbook/.venv/lib/python3.12/site-packages/nbclient/client.py", line 782, in _async_poll_for_reply
    msg = await ensure_async(self.kc.shell_channel.get_msg(timeout=new_timeout))
          ^^^^^^^^^^^^^^^^^^^^^^^^^^^^^^^^^^^^^^^^^^^^^^^^^^^^^^^^^^^^^^^^^^^^^^
  File "/Users/seanwalsh/Documents/GitHub-Mac-Desktop-New/philcompbook/.venv/lib/python3.12/site-packages/jupyter_core/utils/__init__.py", line 198, in ensure_async
    result = await obj
             ^^^^^^^^^
  File "/Users/seanwalsh/Documents/GitHub-Mac-Desktop-New/philcompbook/.venv/lib/python3.12/site-packages/jupyter_client/channels.py", line 315, in get_msg
    raise Empty
_queue.Empty

During handling of the above exception, another exception occurred:

Traceback (most recent call last):
  File "/Users/seanwalsh/Documents/GitHub-Mac-Desktop-New/philcompbook/.venv/lib/python3.12/site-packages/jupyter_cache/executors/utils.py", line 58, in single_nb_execution
    executenb(
  File "/Users/seanwalsh/Documents/GitHub-Mac-Desktop-New/philcompbook/.venv/lib/python3.12/site-packages/nbclient/client.py", line 1314, in execute
    return NotebookClient(nb=nb, resources=resources, km=km, **kwargs).execute()
           ^^^^^^^^^^^^^^^^^^^^^^^^^^^^^^^^^^^^^^^^^^^^^^^^^^^^^^^^^^^^^^^^^^^^^
  File "/Users/seanwalsh/Documents/GitHub-Mac-Desktop-New/philcompbook/.venv/lib/python3.12/site-packages/jupyter_core/utils/__init__.py", line 165, in wrapped
    return loop.run_until_complete(inner)
           ^^^^^^^^^^^^^^^^^^^^^^^^^^^^^^
  File "/Library/Frameworks/Python.framework/Versions/3.12/lib/python3.12/asyncio/base_events.py", line 687, in run_until_complete
    return future.result()
           ^^^^^^^^^^^^^^^
  File "/Users/seanwalsh/Documents/GitHub-Mac-Desktop-New/philcompbook/.venv/lib/python3.12/site-packages/nbclient/client.py", line 709, in async_execute
    await self.async_execute_cell(
  File "/Users/seanwalsh/Documents/GitHub-Mac-Desktop-New/philcompbook/.venv/lib/python3.12/site-packages/nbclient/client.py", line 1005, in async_execute_cell
    exec_reply = await self.task_poll_for_reply
                 ^^^^^^^^^^^^^^^^^^^^^^^^^^^^^^
  File "/Users/seanwalsh/Documents/GitHub-Mac-Desktop-New/philcompbook/.venv/lib/python3.12/site-packages/nbclient/client.py", line 806, in _async_poll_for_reply
    error_on_timeout_execute_reply = await self._async_handle_timeout(timeout, cell)
                                     ^^^^^^^^^^^^^^^^^^^^^^^^^^^^^^^^^^^^^^^^^^^^^^^
  File "/Users/seanwalsh/Documents/GitHub-Mac-Desktop-New/philcompbook/.venv/lib/python3.12/site-packages/nbclient/client.py", line 856, in _async_handle_timeout
    raise CellTimeoutError.error_from_timeout_and_cell(
nbclient.exceptions.CellTimeoutError: A cell timed out while it was being executed, after 30 seconds.
The message was: Cell execution timed out.
Here is a preview of the cell contents:
-------------------
['# here is a python implementation of the ackermann function', '# it works for e.g. 3,2,2 but runs out of time/space for 3,3,3', '', 'import sys', 'sys.setrecursionlimit(10000000)']
...
['    if m==0:', '        return alpha(n,l) ', '    return phi(l-1,n, phi(l,n,m-1)) ', '', 'phi(3,2,3)']
-------------------

